<?xml version="1.0" encoding="utf-8"?>
<!--  
    Date          : 10-03-2023
    Cobot Version : V2 
    Description   : ______
-->
<robot
  name="V2">

  <link
    name="world" />
  <joint name="world_joint" type="fixed">
    <parent link="world" />
    <child link="base_link" />
    <origin
      xyz="0 0 0"
      rpy="0 0 0" />
  </joint>

  <link
    name="base_link">
    <inertial>
      <origin
        xyz="0 0 0"
        rpy="0 0 0" />
      <mass value="100" />
      <inertia
        ixx="2.5"
        ixy="0.0"
        ixz="0.0"
        iyy="2.5"
        iyz="0.0"
        izz="5.0" />
      <!-- <inertia
        ixx="0.48596355"
        ixy="0.00267668"
        ixz="0.01454209"
        iyy="0.47409711"
        iyz="0.06777156"
        izz="0.01851702" /> -->
    </inertial>
    <visual>
      <origin
        xyz="0 0 0"
        rpy="0 0 0" />
      <geometry>
        <mesh
          filename="package://cobot_mesh_loader/meshes/V2/base_link.STL" />
      </geometry>
      <material
        name="">
        <color
          rgba="0.5 0.5 0.5  1" />
      </material>
    </visual>
    <!-- <collision>
      <origin
        xyz="0 0 0"
        rpy="0 0 0" />
      <geometry>
        <mesh
          filename="package://cobot_mesh_loader/meshes/V2/base_link.STL" />
      </geometry> -->
    <!-- </collision> -->
  </link>
  <link
    name="base_turret">
    <inertial>
      <origin
        xyz="-0.00951 -0.04430 0.31057"
        rpy="0 0 0" />
      <mass
        value="4.81" />
      <inertia
        ixx="0.48596355"
        ixy="0.00267668"
        ixz="0.01454209"
        iyy="0.47409711"
        iyz="0.06777156"
        izz="0.01851702" />

    </inertial>
    <visual>
      <origin
        xyz="0 0 0"
        rpy="0 0 0" />
      <geometry>
        <mesh
          filename="package://cobot_mesh_loader/meshes/V2/base_turret.STL" />
      </geometry>
      <material
        name="">
        <color
          rgba="0.75294 0.75294 0.75294 1" />
      </material>
    </visual>
    <collision>
      <origin
        xyz="0 0 0"
        rpy="0 0 0" />
      <geometry>
        <mesh
          filename="package://cobot_mesh_loader/meshes/V2/base_turret.STL" />
      </geometry>
    </collision>
  </link>
  <joint
    name="joint1"
    type="revolute">
    <origin
      xyz="0 0 0"
      rpy="0 0 0" />
    <parent
      link="base_link" />
    <child
      link="base_turret" />
    <axis
      xyz="0 0 -1" />
    <limit
      lower="-3.14159"
      upper="3.14159"
      effort="10000"
      velocity="1000" />
  </joint>
  <link
    name="turret_shoulder">
    <inertial>
      <origin
        xyz="0.38576 -0.00788 0.10204"
        rpy="0 0 0" />
      <mass
        value="2.96" />
      <inertia
        ixx="0.03843596"
        ixy="-0.00690056"
        ixz="0.1100444"
        iyy="0.55409018"
        iyz="0.00216322"
        izz="0.52176272" />
    </inertial>
    <visual>
      <origin
        xyz="0 0 0"
        rpy="0 0 0" />
      <geometry>
        <mesh
          filename="package://cobot_mesh_loader/meshes/V2/turret_shoulder.STL" />
      </geometry>
      <material
        name="">
        <color
          rgba="0.75294 0.75294 0.75294 1" />
      </material>
    </visual>
    <collision>
      <origin
        xyz="0 0 0"
        rpy="0 0 0" />
      <geometry>
        <mesh
          filename="package://cobot_mesh_loader/meshes/V2/turret_shoulder.STL" />
      </geometry>
    </collision>
  </link>
  <joint
    name="joint2"
    type="revolute">
    <origin
      xyz="0 0 0.3175"
      rpy="-1.5708 -1.5708 2.9289" />
    <!-- rpy="-1.5708 -1.0487 2.9289" /> -->
    <parent
      link="base_turret" />
    <child
      link="turret_shoulder" />
    <axis
      xyz="0 0 -1" />
    <limit
      lower="-3.14159"
      upper="3.14159"
      effort="10000"
      velocity="1000" />
  </joint>
  <link
    name="shoulder_elbow">
    <inertial>
      <origin
        xyz="0.00006 0.23938 -0.11678"
        rpy="0 0 0" />
      <mass
        value="2.49" />
      <inertia
        ixx="0.19720434"
        ixy="0.00005402"
        ixz="0.00002998"
        iyy="0.03729153"
        iyz="-0.06571136"
        izz="0.16222013" />
    </inertial>
    <visual>
      <origin
        xyz="0 0 0"
        rpy="0 0 0" />
      <geometry>
        <mesh
          filename="package://cobot_mesh_loader/meshes/V2/shoulder_elbow.STL" />
      </geometry>
      <material
        name="">
        <color
          rgba="0.75294 0.75294 0.75294 1" />
      </material>
    </visual>
    <collision>
      <origin
        xyz="0 0 0"
        rpy="0 0 0" />
      <geometry>
        <mesh
          filename="package://cobot_mesh_loader/meshes/V2/shoulder_elbow.STL" />
      </geometry>
    </collision>
  </link>
  <joint
    name="joint3"
    type="revolute">
    <origin
      xyz="0.47579 0 0"
      rpy="3.1416 0 1.5708" />
    <parent
      link="turret_shoulder" />
    <child
      link="shoulder_elbow" />
    <axis
      xyz="0 0 1" />
    <limit
      lower="-3.14159"
      upper="3.14159"
      effort="10000"
      velocity="1000" />
  </joint>
  <link
    name="elbow_wrist1">
    <inertial>
      <origin
        xyz="0.00026 0.01530 0.55126"
        rpy="0 0 0" />
      <mass
        value="2.45" />
      <inertia
        ixx="0.76047337"
        ixy="0.00001788"
        ixz="0.00035782"
        iyy="0.75777585"
        iyz="0.02254104"
        izz="0.00475183" />
    </inertial>
    <visual>
      <origin
        xyz="0 0 0"
        rpy="0 0 0" />
      <geometry>
        <mesh
          filename="package://cobot_mesh_loader/meshes/V2/elbow_wrist1.STL" />
      </geometry>
      <material
        name="">
        <color
          rgba="0.75294 0.75294 0.75294 1" />
      </material>
    </visual>
    <collision>
      <origin
        xyz="0 0 0"
        rpy="0 0 0" />
      <geometry>
        <mesh
          filename="package://cobot_mesh_loader/meshes/V2/elbow_wrist1.STL" />
      </geometry>
    </collision>
  </link>
  <joint
    name="joint4"
    type="revolute">
    <origin
      xyz="0 0 -0.108"
      rpy="-1.5708 0 0" />
    <parent
      link="shoulder_elbow" />
    <child
      link="elbow_wrist1" />
    <axis
      xyz="0 0 -1" />
    <limit
      lower="-3.14159"
      upper="3.14159"
      effort="10000"
      velocity="1000" />
  </joint>
  <link
    name="wrist1_wrist2">
    <inertial>
      <origin
        xyz="0.07873 0.04741 0.10964"
        rpy="0 0 0" />
      <mass
        value="2.31" />
      <inertia
        ixx="0.036663"
        ixy="0.00930071"
        ixz="0.02028464"
        iyy="0.04527498"
        iyz="0.01220723"
        izz="0.00243441" />
    </inertial>
    <visual>
      <origin
        xyz="0 0 0"
        rpy="0 0 0" />
      <geometry>
        <mesh
          filename="package://cobot_mesh_loader/meshes/V2/wrist1_wrist2.STL" />
      </geometry>
      <material
        name="">
        <color
          rgba="0.5 0.5 0.5  1" />
      </material>
    </visual>
    <collision>
      <origin
        xyz="0 0 0"
        rpy="0 0 0" />
      <geometry>
        <mesh
          filename="package://cobot_mesh_loader/meshes/V2/wrist1_wrist2.STL" />
      </geometry>
    </collision>
  </link>
  <joint
    name="joint5"
    type="revolute">
    <origin
      xyz="0 0 0.576"
      rpy="1.5708 -1.5708 3.1416" />
    <parent
      link="elbow_wrist1" />
    <child
      link="wrist1_wrist2" />
    <axis
      xyz="0 0 -1" />
    <limit
      lower="-3.14159"
      upper="3.14159"
      effort="10000"
      velocity="1000" />
  </joint>
  <link
    name="wrist2_wrist3">
    <inertial>
      <origin
        xyz="1.29913071411636E-08 7.9557968060695E-09 0.0769852478446758"
        rpy="0 0 0" />
      <mass
        value="0.117464996802423" />
      <inertia
        ixx="0.000145537255813443"
        ixy="5.8795158332057E-09"
        ixz="-2.16208204836224E-11"
        iyy="0.000145614246448993"
        iyz="-1.75113630989835E-11"
        izz="9.46318681856647E-05" />
    </inertial>
    <visual>
      <origin
        xyz="0 0 0"
        rpy="0 0 0" />
      <geometry>
        <mesh
          filename="package://cobot_mesh_loader/meshes/V2/wrist2_wrist3.STL" />
      </geometry>
      <material
        name="">
        <color
          rgba="0.866666666666667 0.866666666666667 0.890196078431372 1" />
      </material>
    </visual>
    <collision>
      <origin
        xyz="0 0 0"
        rpy="0 0 0" />
      <geometry>
        <mesh
          filename="package://cobot_mesh_loader/meshes/V2/wrist2_wrist3.STL" />
      </geometry>
    </collision>
  </link>
  <joint
    name="joint6"
    type="revolute">
    <origin
      xyz="0.085 0 0.11131"
      rpy="-1.5708 1.5121 0" />
    <parent
      link="wrist1_wrist2" />
    <child
      link="wrist2_wrist3" />
    <axis
      xyz="0 0 -1" />
    <limit
      lower="-3.14159"
      upper="3.14159"
      effort="10000"
      velocity="1000" />
  </joint>

  <transmission name="joint1_transmission">
    <type>transmission_interface/SimpleTransmission</type>
    <joint name="joint1">
      <hardwareInterface>hardware_interface/EffortJointInterface</hardwareInterface>
    </joint>
    <actuator name="joint1_motor">
      <mechanicalReduction>1</mechanicalReduction>
    </actuator>
  </transmission>
  <transmission name="joint2_transmission">
    <type>transmission_interface/SimpleTransmission</type>
    <joint name="joint2">
      <hardwareInterface>hardware_interface/EffortJointInterface</hardwareInterface>
    </joint>
    <actuator name="joint2_motor">
      <mechanicalReduction>1</mechanicalReduction>
    </actuator>
  </transmission>
  <transmission name="joint3_transmission">
    <type>transmission_interface/SimpleTransmission</type>
    <joint name="joint3">
      <hardwareInterface>hardware_interface/EffortJointInterface</hardwareInterface>
    </joint>
    <actuator name="joint3_motor">
      <mechanicalReduction>1</mechanicalReduction>
    </actuator>
  </transmission>
  <transmission name="joint4_transmission">
    <type>transmission_interface/SimpleTransmission</type>
    <joint name="joint4">
      <hardwareInterface>hardware_interface/EffortJointInterface</hardwareInterface>
    </joint>
    <actuator name="joint4_motor">
      <mechanicalReduction>1</mechanicalReduction>
    </actuator>
  </transmission>
  <transmission name="joint5_transmission">
    <type>transmission_interface/SimpleTransmission</type>
    <joint name="joint5">
      <hardwareInterface>hardware_interface/EffortJointInterface</hardwareInterface>
    </joint>
    <actuator name="joint5_motor">
      <mechanicalReduction>1</mechanicalReduction>
    </actuator>
  </transmission>
  <transmission name="joint6_transmission">
    <type>transmission_interface/SimpleTransmission</type>
    <joint name="joint6">
      <hardwareInterface>hardware_interface/EffortJointInterface</hardwareInterface>
    </joint>
    <actuator name="joint6_motor">
      <mechanicalReduction>1</mechanicalReduction>
    </actuator>
  </transmission>


  <!-- <gazebo reference="base_link">
    <turnGravityOff>true</turnGravityOff>
  </gazebo>

  <gazebo reference="base_turret">
    <turnGravityOff>true</turnGravityOff>
  </gazebo>

  <gazebo reference="turret_shoulder">
    <turnGravityOff>true</turnGravityOff>
  </gazebo>

  <gazebo reference="shoulder_elbow">
    <turnGravityOff>true</turnGravityOff>
  </gazebo>

  <gazebo reference="elbow_wrist1">
    <turnGravityOff>true</turnGravityOff>
  </gazebo>

  <gazebo reference="wrist1_wrist2">
    <turnGravityOff>true</turnGravityOff>
  </gazebo>

  <gazebo reference="wrist2_wrist3">
    <turnGravityOff>true</turnGravityOff>
  </gazebo> -->

  <gazebo>
    <plugin name="gazebo_ros_control" filename="libgazebo_ros_control.so">
    </plugin>
  </gazebo>
</robot>